<?xml version="1.0"?>
<robot xmlns:xacro="http://www.ros.org/wiki/xacro">

<!-- Das ist das Macro für die Chassis. -->
<xacro:macro name="chassis" params="base_name bottom_name top_name ">

	<!-- Hier wird der Körper von der Plattform definiert (Gelb) -->
  <link name="${bottom_name}">
    <visual>
	    <origin rpy="0 0 0" xyz="0 0 0" />
      <geometry>
        <mesh filename="file:///$(find mobi_ros2)/meshes/01_chassis_bottom1.stl" scale="0.001 0.001 0.001" />
      </geometry>
	    <material name="yellow"/>
    </visual>

    <collision>
      <origin rpy="0 0 0" xyz="0 0 0.04" />
      <geometry>
        <box size="0.285 0.198 0.08"/>
      </geometry>
    </collision>

    <inertial>
      <mass value="10"/>
      <origin rpy="0 0 0" xyz="0 0 0.04"/>
       <inertia ixx="0.03267" ixy="0" ixz="0" iyy="0.067688" iyz="0" izz="0.100358"/> 
    </inertial>
  </link>

  <!-- Hier wird die Alu-Platte definiert -->
  <link name="${top_name}">
    <visual>
	    <origin rpy="0 0 0" xyz="0 0 0" />
      <geometry>
        <mesh filename="file:///$(find mobi_ros2)/meshes/02_chassis_top1.stl" scale="0.001 0.001 0.001" />
      </geometry>
	    <material name="light_gray"/>
    </visual>
  </link>

  <!-- Hier wird das Basis Koordinatensystem an den Körper angeheftet -->
  <joint name="${base_name}_to_${bottom_name}_joint" type="fixed">
        <origin xyz="0 0 0" rpy="0 0 0"/>
        <parent link="${base_name}"/>
        <child link="${bottom_name}"/>
  </joint>
  
  <!-- Hier wird die Alu-Platte an den Körper verbunden -->
  <joint name="${bottom_name}_to_${top_name}_joint" type="fixed">
        <origin xyz="0 0 0.08" rpy="0 0 0"/>
        <parent link="${bottom_name}"/>
        <child link="${top_name}"/>
  </joint>

  <!-- Für Gazebo werden hier die Farben der jeweiligen Komponente definiert -->
  <gazebo reference="${bottom_name}">
      <material>Gazebo/Yellow</material> 
  </gazebo>
  <gazebo reference="${top_name}">
      <material>Gazebo/Grey</material>
  </gazebo>

</xacro:macro>


<!-- Das ist das Macro für ein Rad. -->
<xacro:macro name="wheel" params="rim_name screw_name tire_name parent_name direction xyz rpy">
  
  <!-- Felge wird definiert -->
  <link name="${rim_name}">
    <visual>
	    <origin rpy="0 0 0" xyz="0 0 0" />
      <geometry>
        <mesh filename="file:///$(find mobi_ros2)/meshes/09_rim.stl" scale="0.001 0.001 0.001" />
      </geometry>
	    <material name="light_gray"/>
    </visual>
  </link>
  
  <!-- Schraube wird definiert -->
  <link name="${screw_name}">
    <visual>
	    <origin rpy="0 0 0" xyz="0 0 0" />
      <geometry>
        <mesh filename="file:///$(find mobi_ros2)/meshes/10_screw.stl" scale="0.001 0.001 0.001" />
      </geometry>
	    <material name="yellow"/>
    </visual>
  </link>

  <!-- Reifen wird definiert, da der Reifen den Boden berührt bekommt er die Collision und Inertial Komponente dazu-->
  <link name="${tire_name}">
    <visual>
	    <origin rpy="0 0 0" xyz="0 0 0" />
      <geometry>
        <mesh filename="file:///$(find mobi_ros2)/meshes/11_tire.stl" scale="0.001 0.001 0.001" />
      </geometry>
	    <material name="dark_gray"/>
    </visual>

    <collision>
      <origin rpy="0 0 0" xyz="0 0 0.025" />
      <geometry>
        <cylinder radius="0.05" length="0.05"/>
      </geometry>
    </collision>

    <inertial>
      <mass value="0.2"/>
      <origin rpy="0 0 0" xyz="0 0 0.025"/>
      <inertia ixx="0.000167" ixy="0" ixz="0" iyy="0.000167" iyz="0" izz="0.00025"/>
    </inertial>
  </link>

  <!-- In den folgenden drei Joint, werden die Verbindungen erstellt -->
   <joint name="${rim_name}_to_${screw_name}_joint" type="fixed">
        <origin xyz="0 0 0.042" rpy="0 0 0"/>
        <parent link="${rim_name}"/>
        <child link="${screw_name}"/>
  </joint>

  <joint name="${rim_name}_to_${tire_name}_joint" type="fixed">
        <origin xyz="0 0 0" rpy="0 0 0"/>
        <parent link="${rim_name}"/>
        <child link="${tire_name}"/>
  </joint>

  <joint name="${parent_name}_to_${rim_name}_joint" type="continuous">
        <origin xyz="${xyz}" rpy="${rpy}"/>
        <parent link="chassis_bottom_link"/>
        <child link="${rim_name}"/>
        <axis xyz="0 0 ${direction}"/>
  </joint>

  <!-- Farben für Gazebo werden hier definiert -->
  <gazebo reference="${rim_name}">
      <material>Gazebo/CoM</material>
  </gazebo>

  <gazebo reference="${screw_name}">
      <material>Gazebo/White</material>
  </gazebo>

  <!-- Beim Reifen werden die Steifigkeit und Reibungskoeffizienten defineirt -->
  <gazebo reference="${tire_name}">
      <material>Gazebo/FlatBlack</material>
      <kp>10000000000.0</kp>
      <kd>10000000000.0</kd>
      <mu1>200.0</mu1>
      <mu2>100.0</mu2>
  </gazebo>

  </xacro:macro>

</robot>